---
title: AsyncGenerator.prototype.throw()
slug: Web/JavaScript/Reference/Global_Objects/AsyncGenerator/throw
tags:
- ECMAScript 2018
- AsyncGenerator
- JavaScript
- Method
- Prototype
- Reference
---
<div>{{JSRef}}</div>

<p><span class="seoSummary">The <strong><code>throw()</code></strong> method resumes the execution of a generator by throwing an error into it and returns an object with two properties <code>done</code> and <code>value</code>.</span></p>

<h2 id="Syntax">Syntax</h2>

<pre
  class="brush: js"><code><var>asyncGen</var>.throw(<var>exception</var>)</code></pre>

<h3 id="Parameters">Parameters</h3>

<dl>
  <dt><code><var>exception</var></code></dt>
  <dd>The exception to throw. For debugging purposes, it is useful to make it an <code>instanceof</code> {{jsxref("Error")}}.</dd>
</dl>

<h3 id="Return_value">Return value</h3>

<p>An {{jsxref("Global_Objects/Object", "Object")}} with two properties:</p>

<dl>
  <dt><code>done</code> (boolean)</dt>
  <dd>
    <ul>
      <li>Has the value <code>true</code> if the iterator is past the end of the iterated sequence. In this case <code>value</code> optionally specifies the <em>return value</em> of the iterator.</li>
      <li>Has the value <code>false</code> if the iterator was able to produce the next value in the sequence. This is equivalent of not specifying the <code>done</code> property altogether.</li>
    </ul>
  </dd>
  <dt><code>value</code></dt>
  <dd>Any JavaScript value returned by the iterator. Can be omitted when <code>done</code> is <code>true</code>.</dd>
</dl>

<h2 id="Examples">Examples</h2>

<h3 id="Using_throw">Using throw()</h3>

<p>The following example shows a simple generator and an error that is thrown using the <code>throw</code> method. An error can be caught by a {{jsxref("Statements/try...catch", "try...catch")}} block as usual.</p>

<pre class="brush: js">async function* createAsyncGenerator() {
  while(true) {
    try {
       yield 42;
    } catch(e) {
      console.log('Error caught!');
    }
  }
}

const asyncGen = createAsyncGenerator();
asyncGen.next(1).then(res => console.log(res));
// { value: 42, done: false }
asyncGen.throw(new Error('Something went wrong')).then(res => console.log(res));
// "Error caught!"
// { value: 42, done: false }
</pre>

<h2 id="Specifications">Specifications</h2>

<table class="standard-table">
  <thead>
    <tr>
      <th scope="col">Specification</th>
    </tr>
  </thead>
  <tbody>
    <tr>
      <td>{{SpecName('ESDraft', '#sec-asyncgenerator-prototype-throw', 'AsyncGenerator.prototype.throw')}}</td>
    </tr>
  </tbody>
</table>

<h2 id="Browser_compatibility">Browser compatibility</h2>

<p>{{Compat("javascript.builtins.AsyncGenerator.throw")}}</p>

<h2 id="See_also">See also</h2>

<ul>
  <li>{{jsxref("Statements/async_function*", "async function*")}}</li>
  <li><a href="/en-US/docs/Web/JavaScript/Guide/Iterators_and_Generators">Iterators and generators</a></li>
</ul>
